<?xml version="1.0" ?>
<robot name="CatModel">

<material name="white">
  <color rgba="0.900 0.900 0.900 1.000"/>
</material>
<material name="ginger">
  <color rgba="0.750 0.500 0.250 1.000"/>
</material>
<material name="green">
  <color rgba="0.1 0.4 0.15 1.000"/>
</material>
<material name="black">
  <color rgba="0.3 0.3 0.3 1.000"/>
</material>
<material name="wood">
  <color rgba="0.6921 0.4431 0.2471 1.000"/>
</material>


<link name="base_link">
  <inertial>
    <origin rpy="0 0 0" xyz="4.828448836566253e-06 -4.612760516553384e-05 0.08481287235367217"/>
    <mass value="0.23060219033668225"/>
    <inertia ixx="0.00039234043563495403" ixy="3.512742743516971e-10" ixz="6.388681870906491e-08" iyy="0.0008625315560529527" iyz="1.8805183007303448e-07" izz="0.0011563335808692746"/>
  </inertial>
  <visual>
    <origin rpy="0 0 0" xyz="0 0 0"/>
    <geometry>
      <mesh filename="meshes/base_link.stl" scale="0.001 0.001 0.001"/>
    </geometry>
    <material name="wood"/>
    <material/>
  </visual>
  <collision>
    <origin rpy="0 0 0" xyz="0 0 0"/>
    <geometry>
      <mesh filename="meshes/base_link.stl" scale="0.001 0.001 0.001"/>
    </geometry>
  </collision>
</link>

<link name="Upper_Right_Rear_Servo1">
  <inertial>
    <origin rpy="0 0 0" xyz="-0.008705058252338416 -0.012500000000000011 -0.0085208055109922"/>
    <mass value="0.08892951704871728"/>
    <inertia ixx="1.135906857503764e-05" ixy="-7.563772916319416e-07" ixz="-5.877350762054003e-06" iyy="1.7308522848490148e-05" iyz="-5.648893697169136e-07" izz="1.1518336968654986e-05"/>
  </inertial>
  <visual>
    <origin rpy="0 0 0" xyz="0.074132 0.05 -0.094571"/>
    <geometry>
      <mesh filename="meshes/Upper_Right_Rear_Servo1.stl" scale="0.001 0.001 0.001"/>
    </geometry>
    <material name="black"/>
    <material/>
  </visual>
  <collision>
    <origin rpy="0 0 0" xyz="0.074132 0.05 -0.094571"/>
    <geometry>
      <mesh filename="meshes/Upper_Right_Rear_Servo1.stl" scale="0.001 0.001 0.001"/>
    </geometry>
  </collision>
</link>

<link name="Upper_Right_Rear_Leg1">
  <inertial>
    <origin rpy="0 0 0" xyz="-1.2657987762065837e-05 0.0 -0.032742712255466"/>
    <mass value="0.014216059949049762"/>
    <inertia ixx="9.14897082191506e-06" ixy="1.3552527156068805e-20" ixz="4.363359273776377e-11" iyy="1.0082257104575791e-05" iyz="-6.776263578034403e-21" izz="1.1702206151449038e-06"/>
  </inertial>
  <visual>
    <origin rpy="0 0 0" xyz="0.089932 0.075 -0.082771"/>
    <geometry>
      <mesh filename="meshes/Upper_Right_Rear_Leg1.stl" scale="0.001 0.001 0.001"/>
    </geometry>
    <material name="wood"/>
    <material/>
  </visual>
  <collision>
    <origin rpy="0 0 0" xyz="0.089932 0.075 -0.082771"/>
    <geometry>
      <mesh filename="meshes/Upper_Right_Rear_Leg1.stl" scale="0.001 0.001 0.001"/>
    </geometry>
  </collision>
</link>

<link name="Right_Rear_Joint1">
  <inertial>
    <origin rpy="0 0 0" xyz="1.0268760365639285e-07 -5.551115123125783e-17 -2.534658303382509e-07"/>
    <mass value="0.0049939542219628675"/>
    <inertia ixx="6.689817351290575e-08" ixy="6.776263578034403e-21" ixz="-6.776263578034403e-21" iyy="5.0563783211123395e-08" iyz="-4.235164736271502e-21" izz="6.689818006422787e-08"/>
  </inertial>
  <visual>
    <origin rpy="0 0 0" xyz="0.089935 0.075 -0.017438"/>
    <geometry>
      <mesh filename="meshes/Right_Rear_Joint1.stl" scale="0.001 0.001 0.001"/>
    </geometry>
    <material name="black"/>
    <material/>
  </visual>
  <collision>
    <origin rpy="0 0 0" xyz="0.089935 0.075 -0.017438"/>
    <geometry>
      <mesh filename="meshes/Right_Rear_Joint1.stl" scale="0.001 0.001 0.001"/>
    </geometry>
  </collision>
</link>

<link name="Lower_Right_Rear_Servo1">
  <inertial>
    <origin rpy="0 0 0" xyz="-0.007162372290249686 0.016937460430151777 -2.5371486519001896e-07"/>
    <mass value="0.08509975852435848"/>
    <inertia ixx="4.855585193670763e-06" ixy="3.4288186995658047e-07" ixz="-7.153050938027428e-15" iyy="1.6667817887716478e-05" iyz="1.1921792220960514e-14" izz="1.606662677382394e-05"/>
  </inertial>
  <visual>
    <origin rpy="0 0 0" xyz="0.089935 0.07 -0.017438"/>
    <geometry>
      <mesh filename="meshes/Lower_Right_Rear_Servo1.stl" scale="0.001 0.001 0.001"/>
    </geometry>
    <material name="black"/>
    <material/>
  </visual>
  <collision>
    <origin rpy="0 0 0" xyz="0.089935 0.07 -0.017438"/>
    <geometry>
      <mesh filename="meshes/Lower_Right_Rear_Servo1.stl" scale="0.001 0.001 0.001"/>
    </geometry>
  </collision>
</link>

<link name="Lower_Right_Rear_Leg1">
  <inertial>
    <origin rpy="0 0 0" xyz="-0.023689841493032673 1.3877787807814457e-17 -0.0010777696278954432"/>
    <mass value="0.012527915218877675"/>
    <inertia ixx="8.92584988676055e-07" ixy="-4.0657581468206416e-20" ixz="-2.885026995442547e-07" iyy="7.94106993199357e-06" iyz="-1.6940658945086007e-21" izz="7.257283530298864e-06"/>
  </inertial>
  <visual>
    <origin rpy="0 0 0" xyz="0.089935 0.065 -0.017438"/>
    <geometry>
      <mesh filename="meshes/Lower_Right_Rear_Leg1.stl" scale="0.001 0.001 0.001"/>
    </geometry>
    <material name="wood"/>
    <material/>
  </visual>
  <collision>
    <origin rpy="0 0 0" xyz="0.089935 0.065 -0.017438"/>
    <geometry>
      <mesh filename="meshes/Lower_Right_Rear_Leg1.stl" scale="0.001 0.001 0.001"/>
    </geometry>
  </collision>
</link>

<link name="Right_Rear_Paw1">
  <inertial>
    <origin rpy="0 0 0" xyz="7.511135047266748e-09 0.0 4.805733764823295e-07"/>
    <mass value="0.009860673647584237"/>
    <inertia ixx="7.395505070385559e-07" ixy="2.710505431213761e-20" ixz="3.3881317890172014e-21" iyy="1.1093257522928218e-06" iyz="-1.6940658945086007e-21" izz="7.39550507038644e-07"/>
  </inertial>
  <visual>
    <origin rpy="0 0 0" xyz="0.159944 0.065 -0.01611"/>
    <geometry>
      <mesh filename="meshes/Right_Rear_Paw1.stl" scale="0.001 0.001 0.001"/>
    </geometry>
    <material name="white"/>
    <material/>
  </visual>
  <collision>
    <origin rpy="0 0 0" xyz="0.159944 0.065 -0.01611"/>
    <geometry>
      <mesh filename="meshes/Right_Rear_Paw1.stl" scale="0.001 0.001 0.001"/>
    </geometry>
  </collision>
</link>

<link name="Upper_Right_Front_Servo1">
  <inertial>
    <origin rpy="0 0 0" xyz="0.008764782542449959 -0.012499999999999997 -0.00865448803477041"/>
    <mass value="0.08892951704871722"/>
    <inertia ixx="1.1398601763720805e-05" ixy="8.194267562608025e-07" ixz="5.933694709349792e-06" iyy="1.7425996599347918e-05" iyz="-6.241495982671095e-07" izz="1.1596277530830025e-05"/>
  </inertial>
  <visual>
    <origin rpy="0 0 0" xyz="-0.072881 0.05 -0.095719"/>
    <geometry>
      <mesh filename="meshes/Upper_Right_Front_Servo1.stl" scale="0.001 0.001 0.001"/>
    </geometry>
    <material name="black"/>
    <material/>
  </visual>
  <collision>
    <origin rpy="0 0 0" xyz="-0.072881 0.05 -0.095719"/>
    <geometry>
      <mesh filename="meshes/Upper_Right_Front_Servo1.stl" scale="0.001 0.001 0.001"/>
    </geometry>
  </collision>
</link>

<link name="Upper_Right_Front_Leg1">
  <inertial>
    <origin rpy="0 0 0" xyz="-8.530472696814673e-05 0.0 -0.03273740647087604"/>
    <mass value="0.014216059949049762"/>
    <inertia ixx="9.14492261793487e-06" ixy="1.3552527156068805e-20" ixz="8.963002220437446e-10" iyy="1.0078205657321909e-05" iyz="6.776263578034403e-21" izz="1.1702173718711986e-06"/>
  </inertial>
  <visual>
    <origin rpy="0 0 0" xyz="-0.089998 0.075 -0.082681"/>
    <geometry>
      <mesh filename="meshes/Upper_Right_Front_Leg1.stl" scale="0.001 0.001 0.001"/>
    </geometry>
    <material name="wood"/>
    <material/>
  </visual>
  <collision>
    <origin rpy="0 0 0" xyz="-0.089998 0.075 -0.082681"/>
    <geometry>
      <mesh filename="meshes/Upper_Right_Front_Leg1.stl" scale="0.001 0.001 0.001"/>
    </geometry>
  </collision>
</link>

<link name="Right_Front_Joint1">
  <inertial>
    <origin rpy="0 0 0" xyz="-2.402333844908622e-07 -5.551115123125783e-17 -4.584168129713462e-07"/>
    <mass value="0.0049939542219628675"/>
    <inertia ixx="6.689817351291253e-08" ixy="-2.0328790734103208e-20" ixz="3.3881317890172014e-21" iyy="5.0563783211123395e-08" iyz="-4.235164736271502e-21" izz="6.689818006421432e-08"/>
  </inertial>
  <visual>
    <origin rpy="0 0 0" xyz="-0.089937 0.075 -0.01721"/>
    <geometry>
      <mesh filename="meshes/Right_Front_Joint1.stl" scale="0.001 0.001 0.001"/>
    </geometry>
    <material name="black"/>
    <material/>
  </visual>
  <collision>
    <origin rpy="0 0 0" xyz="-0.089937 0.075 -0.01721"/>
    <geometry>
      <mesh filename="meshes/Right_Front_Joint1.stl" scale="0.001 0.001 0.001"/>
    </geometry>
  </collision>
</link>

<link name="Lower_Right_Front_Servo1">
  <inertial>
    <origin rpy="0 0 0" xyz="0.007162237945319436 0.01693746043015179 9.504163804588059e-05"/>
    <mass value="0.0850997585243585"/>
    <inertia ixx="4.855621768028076e-06" ixy="-3.4288202332266983e-07" ixz="-2.7430668549045713e-09" iyy="1.6667854646112935e-05" iyz="-4.571776864647028e-09" izz="1.6066626957863574e-05"/>
  </inertial>
  <visual>
    <origin rpy="0 0 0" xyz="-0.089937 0.07 -0.01721"/>
    <geometry>
      <mesh filename="meshes/Lower_Right_Front_Servo1.stl" scale="0.001 0.001 0.001"/>
    </geometry>
    <material name="black"/>
    <material/>
  </visual>
  <collision>
    <origin rpy="0 0 0" xyz="-0.089937 0.07 -0.01721"/>
    <geometry>
      <mesh filename="meshes/Lower_Right_Front_Servo1.stl" scale="0.001 0.001 0.001"/>
    </geometry>
  </collision>
</link>

<link name="Lower_Right_Front_Leg1">
  <inertial>
    <origin rpy="0 0 0" xyz="0.02365871265081529 0.0 -0.0009338965652742164"/>
    <mass value="0.012527915218877713"/>
    <inertia ixx="8.927102762511694e-07" ixy="1.3552527156068805e-20" ixz="2.8999114412186076e-07" iyy="7.941829753251186e-06" iyz="0.0" izz="7.257918063981379e-06"/>
  </inertial>
  <visual>
    <origin rpy="0 0 0" xyz="-0.089937 0.065 -0.01721"/>
    <geometry>
      <mesh filename="meshes/Lower_Right_Front_Leg1.stl" scale="0.001 0.001 0.001"/>
    </geometry>
    <material name="wood"/>
    <material/>
  </visual>
  <collision>
    <origin rpy="0 0 0" xyz="-0.089937 0.065 -0.01721"/>
    <geometry>
      <mesh filename="meshes/Lower_Right_Front_Leg1.stl" scale="0.001 0.001 0.001"/>
    </geometry>
  </collision>
</link>

<link name="Right_Front_Paw1">
  <inertial>
    <origin rpy="0 0 0" xyz="-6.66422521056198e-08 0.0 3.8056695783258987e-07"/>
    <mass value="0.009860673647584237"/>
    <inertia ixx="7.39550507038583e-07" ixy="5.421010862427522e-20" ixz="-1.0164395367051604e-20" iyy="1.1093257522928218e-06" iyz="3.3881317890172014e-21" izz="7.39550507038644e-07"/>
  </inertial>
  <visual>
    <origin rpy="0 0 0" xyz="-0.159916 0.065 -0.016021"/>
    <geometry>
      <mesh filename="meshes/Right_Front_Paw1.stl" scale="0.001 0.001 0.001"/>
    </geometry>
    <material name="white"/>
    <material/>
  </visual>
  <collision>
    <origin rpy="0 0 0" xyz="-0.159916 0.065 -0.016021"/>
    <geometry>
      <mesh filename="meshes/Right_Front_Paw1.stl" scale="0.001 0.001 0.001"/>
    </geometry>
  </collision>
</link>

<link name="Neck_Servo1">
  <inertial>
    <origin rpy="0 0 0" xyz="0.012088780175495181 1.9515253796303132e-07 0.0025195800527267748"/>
    <mass value="0.08701463778653835"/>
    <inertia ixx="1.0888447279340432e-05" ixy="-1.0428525193303775e-10" ixz="5.772983643664484e-06" iyy="1.6226212828070966e-05" iyz="-1.8797429805778473e-10" izz="1.0813930154036293e-05"/>
  </inertial>
  <visual>
    <origin rpy="0 0 0" xyz="-0.079697 -0.0 -0.112197"/>
    <geometry>
      <mesh filename="meshes/Neck_Servo1.stl" scale="0.001 0.001 0.001"/>
    </geometry>
    <material name="black"/>
    <material/>
  </visual>
  <collision>
    <origin rpy="0 0 0" xyz="-0.079697 -0.0 -0.112197"/>
    <geometry>
      <mesh filename="meshes/Neck_Servo1.stl" scale="0.001 0.001 0.001"/>
    </geometry>
  </collision>
</link>

<link name="Neck1">
  <inertial>
    <origin rpy="0 0 0" xyz="0.01123427725955535 0.0009221597976449781 -0.0020048734460798023"/>
    <mass value="0.19671474883465964"/>
    <inertia ixx="0.00011974818810461373" ixy="-2.9831136313045425e-06" ixz="2.761469197435241e-06" iyy="3.5474452138836536e-05" iyz="3.4391210002771794e-07" izz="0.00014274235119378842"/>
  </inertial>
  <visual>
    <origin rpy="0 0 0" xyz="-0.097927 -4e-06 -0.125786"/>
    <geometry>
      <mesh filename="meshes/Neck1.stl" scale="0.001 0.001 0.001"/>
    </geometry>
    <material name="wood"/>
    <material/>
  </visual>
  <collision>
    <origin rpy="0 0 0" xyz="-0.097927 -4e-06 -0.125786"/>
    <geometry>
      <mesh filename="meshes/Neck1.stl" scale="0.001 0.001 0.001"/>
    </geometry>
  </collision>
</link>

<link name="Head_Servo1">
  <inertial>
    <origin rpy="0 0 0" xyz="-0.00020573526206899007 0.0144488827820353 0.012506366679220726"/>
    <mass value="0.07800761310887962"/>
    <inertia ixx="1.7514893352275126e-05" ixy="1.1964101534863358e-08" ixz="1.0356017418828092e-08" iyy="1.5420048085610077e-05" iyz="-6.28035148224007e-07" izz="4.915631620179637e-06"/>
  </inertial>
  <visual>
    <origin rpy="0 0 0" xyz="-0.125283 0.030014 -0.121923"/>
    <geometry>
      <mesh filename="meshes/Head_Servo1.stl" scale="0.001 0.001 0.001"/>
    </geometry>
    <material name="black"/>
    <material/>
  </visual>
  <collision>
    <origin rpy="0 0 0" xyz="-0.125283 0.030014 -0.121923"/>
    <geometry>
      <mesh filename="meshes/Head_Servo1.stl" scale="0.001 0.001 0.001"/>
    </geometry>
  </collision>
</link>

<link name="Head1">
  <inertial>
    <origin rpy="0 0 0" xyz="0.025829653601937175 0.016968693548665863 0.006114881070728717"/>
    <mass value="0.8146696853490065"/>
    <inertia ixx="0.00037625933598252857" ixy="-4.1032021073195805e-06" ixz="3.5163968085536595e-05" iyy="0.0003134078855276251" iyz="-9.583909859524562e-07" izz="0.00028820425441944755"/>
  </inertial>
  <visual>
    <origin rpy="0 0 0" xyz="-0.125067 0.017047 -0.128159"/>
    <geometry>
      <mesh filename="meshes/Head1.stl" scale="0.001 0.001 0.001"/>
    </geometry>
    <material name="wood"/>
    <material/>
  </visual>
  <collision>
    <origin rpy="0 0 0" xyz="-0.125067 0.017047 -0.128159"/>
    <geometry>
      <mesh filename="meshes/Head1.stl" scale="0.001 0.001 0.001"/>
    </geometry>
  </collision>
</link>

<link name="Electronics1">
  <inertial>
    <origin rpy="0 0 0" xyz="0.002491103479004657 -0.047323940408980275 -9.006928508581424e-08"/>
    <mass value="0.1587634595739255"/>
    <inertia ixx="0.00010941324576018395" ixy="6.962056449767063e-08" ixz="2.238714855856694e-15" iyy="0.00012028852864303611" iyz="-4.253452897580727e-14" izz="0.0002270595662496503"/>
  </inertial>
  <visual>
    <origin rpy="0 0 0" xyz="7.2e-05 -0.0475 -0.102498"/>
    <geometry>
      <mesh filename="meshes/Electronics1.stl" scale="0.001 0.001 0.001"/>
    </geometry>
    <material name="green"/>
    <material/>
  </visual>
  <collision>
    <origin rpy="0 0 0" xyz="7.2e-05 -0.0475 -0.102498"/>
    <geometry>
      <mesh filename="meshes/Electronics1.stl" scale="0.001 0.001 0.001"/>
    </geometry>
  </collision>
</link>

<link name="Battery1">
  <inertial>
    <origin rpy="0 0 0" xyz="0.004970720042067048 0.0 -0.014912160126184536"/>
    <mass value="0.6539897585243583"/>
    <inertia ixx="0.00021762795239984407" ixy="-1.3687895261682568e-19" ixz="2.855498617997977e-07" iyy="0.00046153313567702265" iyz="3.421973815420642e-20" izz="0.0006340399595973334"/>
  </inertial>
  <visual>
    <origin rpy="0 0 0" xyz="-0.0 -0.0 -0.0725"/>
    <geometry>
      <mesh filename="meshes/Battery1.stl" scale="0.001 0.001 0.001"/>
    </geometry>
    <material name="ginger"/>
    <material/>
  </visual>
  <collision>
    <origin rpy="0 0 0" xyz="-0.0 -0.0 -0.0725"/>
    <geometry>
      <mesh filename="meshes/Battery1.stl" scale="0.001 0.001 0.001"/>
    </geometry>
  </collision>
</link>

<link name="Tail_Servo1">
  <inertial>
    <origin rpy="0 0 0" xyz="-0.011922412265587129 -4.994581944007777e-07 0.0026566674441921845"/>
    <mass value="0.08689583836578228"/>
    <inertia ixx="1.120967849619443e-05" ixy="-1.1321282747178476e-10" ixz="-5.899813467811739e-06" iyy="1.6421647025098834e-05" iyz="6.291786786704317e-10" izz="1.0686648969213531e-05"/>
  </inertial>
  <visual>
    <origin rpy="0 0 0" xyz="0.079697 -0.0 -0.112197"/>
    <geometry>
      <mesh filename="meshes/Tail_Servo1.stl" scale="0.001 0.001 0.001"/>
    </geometry>
    <material name="black"/>
    <material/>
  </visual>
  <collision>
    <origin rpy="0 0 0" xyz="0.079697 -0.0 -0.112197"/>
    <geometry>
      <mesh filename="meshes/Tail_Servo1.stl" scale="0.001 0.001 0.001"/>
    </geometry>
  </collision>
</link>

<link name="Tail1">
  <inertial>
    <origin rpy="0 0 0" xyz="-0.04895558163064957 1.2304007942038428e-05 -0.0489557172543776"/>
    <mass value="0.01723009674422482"/>
    <inertia ixx="1.7307019228040223e-05" ixy="-2.564355892630473e-10" ixz="-1.6576968536536994e-05" iyy="3.344110535214416e-05" iyz="-2.564355892619882e-10" izz="1.730701922804021e-05"/>
  </inertial>
  <visual>
    <origin rpy="0 0 0" xyz="0.094118 1.2e-05 -0.12924"/>
    <geometry>
      <mesh filename="meshes/Tail1.stl" scale="0.001 0.001 0.001"/>
    </geometry>
    <material name="wood"/>
    <material/>
  </visual>
  <collision>
    <origin rpy="0 0 0" xyz="0.094118 1.2e-05 -0.12924"/>
    <geometry>
      <mesh filename="meshes/Tail1.stl" scale="0.001 0.001 0.001"/>
    </geometry>
  </collision>
</link>

<link name="Upper_Left_Rear_Servo1">
  <inertial>
    <origin rpy="0 0 0" xyz="-0.008709364762219271 0.012499999999999997 -0.008616498998876135"/>
    <mass value="0.08892951704871722"/>
    <inertia ixx="1.1365631716438868e-05" ixy="7.611644897254988e-07" ixz="-5.8819421199607196e-06" iyy="1.7320556993317493e-05" iyz="5.696765677650427e-07" izz="1.1523807972080888e-05"/>
  </inertial>
  <visual>
    <origin rpy="0 0 0" xyz="0.074132 -0.05 -0.094571"/>
    <geometry>
      <mesh filename="meshes/Upper_Left_Rear_Servo1.stl" scale="0.001 0.001 0.001"/>
    </geometry>
    <material name="black"/>
    <material/>
  </visual>
  <collision>
    <origin rpy="0 0 0" xyz="0.074132 -0.05 -0.094571"/>
    <geometry>
      <mesh filename="meshes/Upper_Left_Rear_Servo1.stl" scale="0.001 0.001 0.001"/>
    </geometry>
  </collision>
</link>

<link name="Upper_Left_Rear_Leg1">
  <inertial>
    <origin rpy="0 0 0" xyz="6.0257715295247705e-05 0.0 -0.03272038914643548"/>
    <mass value="0.014216059949049762"/>
    <inertia ixx="9.147187959461728e-06" ixy="0.0" ixz="-8.420847599950598e-10" iyy="1.0080472775197583e-05" iyz="2.0328790734103208e-20" izz="1.1702191482200692e-06"/>
  </inertial>
  <visual>
    <origin rpy="0 0 0" xyz="0.090032 -0.075 -0.082671"/>
    <geometry>
      <mesh filename="meshes/Upper_Left_Rear_Leg1.stl" scale="0.001 0.001 0.001"/>
    </geometry>
    <material name="wood"/>
    <material/>
  </visual>
  <collision>
    <origin rpy="0 0 0" xyz="0.090032 -0.075 -0.082671"/>
    <geometry>
      <mesh filename="meshes/Upper_Left_Rear_Leg1.stl" scale="0.001 0.001 0.001"/>
    </geometry>
  </collision>
</link>

<link name="Left_Rear_Joint1">
  <inertial>
    <origin rpy="0 0 0" xyz="4.96095167820676e-07 1.3877787807814457e-17 -3.0490204138561294e-07"/>
    <mass value="0.0049939542219629126"/>
    <inertia ixx="6.689817355522013e-08" ixy="0.0" ixz="-5.082197683525802e-21" iyy="5.0563783253414056e-08" iyz="3.3881317890172014e-21" izz="6.689818006425498e-08"/>
  </inertial>
  <visual>
    <origin rpy="0 0 0" xyz="0.089975 -0.075 -0.017277"/>
    <geometry>
      <mesh filename="meshes/Left_Rear_Joint1.stl" scale="0.001 0.001 0.001"/>
    </geometry>
    <material name="black"/>
    <material/>
  </visual>
  <collision>
    <origin rpy="0 0 0" xyz="0.089975 -0.075 -0.017277"/>
    <geometry>
      <mesh filename="meshes/Left_Rear_Joint1.stl" scale="0.001 0.001 0.001"/>
    </geometry>
  </collision>
</link>

<link name="Lower_Left_Rear_Servo1">
  <inertial>
    <origin rpy="0 0 0" xyz="-0.0071619820835361475 -0.01693746043015177 9.519515281747326e-05"/>
    <mass value="0.0850997585243585"/>
    <inertia ixx="4.855621768027859e-06" ixy="-3.4288202332283246e-07" ixz="2.7430668548774663e-09" iyy="1.666785464611261e-05" iyz="4.571776864647028e-09" izz="1.6066626957863357e-05"/>
  </inertial>
  <visual>
    <origin rpy="0 0 0" xyz="0.089975 -0.07 -0.017277"/>
    <geometry>
      <mesh filename="meshes/Lower_Left_Rear_Servo1.stl" scale="0.001 0.001 0.001"/>
    </geometry>
    <material name="black"/>
    <material/>
  </visual>
  <collision>
    <origin rpy="0 0 0" xyz="0.089975 -0.07 -0.017277"/>
    <geometry>
      <mesh filename="meshes/Lower_Left_Rear_Servo1.stl" scale="0.001 0.001 0.001"/>
    </geometry>
  </collision>
</link>

<link name="Lower_Left_Rear_Leg1">
  <inertial>
    <origin rpy="0 0 0" xyz="-0.023679100821470664 -1.3877787807814457e-17 -0.0009947104633864674"/>
    <mass value="0.012527915218877675"/>
    <inertia ixx="8.926594507867674e-07" ixy="1.3552527156068805e-20" ixz="-2.8935853395577966e-07" iyy="7.941356342554203e-06" iyz="-3.3881317890172014e-21" izz="7.257495478748784e-06"/>
  </inertial>
  <visual>
    <origin rpy="0 0 0" xyz="0.089975 -0.065 -0.017277"/>
    <geometry>
      <mesh filename="meshes/Lower_Left_Rear_Leg1.stl" scale="0.001 0.001 0.001"/>
    </geometry>
    <material name="wood"/>
    <material/>
  </visual>
  <collision>
    <origin rpy="0 0 0" xyz="0.089975 -0.065 -0.017277"/>
    <geometry>
      <mesh filename="meshes/Lower_Left_Rear_Leg1.stl" scale="0.001 0.001 0.001"/>
    </geometry>
  </collision>
</link>

<link name="Left_Rear_Paw1">
  <inertial>
    <origin rpy="0 0 0" xyz="3.9103137530749343e-07 0.0 -3.2894929649293636e-07"/>
    <mass value="0.009860673647584237"/>
    <inertia ixx="7.395505070385627e-07" ixy="-1.3552527156068805e-20" ixz="6.776263578034403e-21" iyy="1.1093257522927676e-06" iyz="0.0" izz="7.39550507038644e-07"/>
  </inertial>
  <visual>
    <origin rpy="0 0 0" xyz="0.159974 -0.065 -0.01603"/>
    <geometry>
      <mesh filename="meshes/Left_Rear_Paw1.stl" scale="0.001 0.001 0.001"/>
    </geometry>
    <material name="white"/>
    <material/>
  </visual>
  <collision>
    <origin rpy="0 0 0" xyz="0.159974 -0.065 -0.01603"/>
    <geometry>
      <mesh filename="meshes/Left_Rear_Paw1.stl" scale="0.001 0.001 0.001"/>
    </geometry>
  </collision>
</link>

<link name="Upper_Left_Front_Servo1">
  <inertial>
    <origin rpy="0 0 0" xyz="0.008785081078021909 0.012500000000000011 -0.008557021808984433"/>
    <mass value="0.08892951704871721"/>
    <inertia ixx="1.1393842768754473e-05" ixy="-8.158511247008133e-07" ixz="5.931342781384367e-06" iyy="1.7416579238026383e-05" iyz="6.221706832519646e-07" izz="1.1591619164474606e-05"/>
  </inertial>
  <visual>
    <origin rpy="0 0 0" xyz="-0.072933 -0.05 -0.095716"/>
    <geometry>
      <mesh filename="meshes/Upper_Left_Front_Servo1.stl" scale="0.001 0.001 0.001"/>
    </geometry>
    <material name="black"/>
    <material/>
  </visual>
  <collision>
    <origin rpy="0 0 0" xyz="-0.072933 -0.05 -0.095716"/>
    <geometry>
      <mesh filename="meshes/Upper_Left_Front_Servo1.stl" scale="0.001 0.001 0.001"/>
    </geometry>
  </collision>
</link>

<link name="Upper_Left_Front_Leg1">
  <inertial>
    <origin rpy="0 0 0" xyz="-1.539053799046175e-05 0.0 -0.032681677799056105"/>
    <mass value="0.014216059949049762"/>
    <inertia ixx="9.149053204176704e-06" ixy="-1.3552527156068805e-20" ixz="4.2685382626531793e-10" iyy="1.0082339403517379e-05" iyz="-6.776263578034403e-21" izz="1.1702205318248613e-06"/>
  </inertial>
  <visual>
    <origin rpy="0 0 0" xyz="-0.089975 -0.075 -0.08272"/>
    <geometry>
      <mesh filename="meshes/Upper_Left_Front_Leg1.stl" scale="0.001 0.001 0.001"/>
    </geometry>
    <material name="wood"/>
    <material/>
  </visual>
  <collision>
    <origin rpy="0 0 0" xyz="-0.089975 -0.075 -0.08272"/>
    <geometry>
      <mesh filename="meshes/Upper_Left_Front_Leg1.stl" scale="0.001 0.001 0.001"/>
    </geometry>
  </collision>
</link>

<link name="Left_Front_Joint1">
  <inertial>
    <origin rpy="0 0 0" xyz="2.345907219869492e-08 1.3877787807814457e-17 -5.326294378119045e-08"/>
    <mass value="0.0049939542219629126"/>
    <inertia ixx="6.689817355521674e-08" ixy="0.0" ixz="3.3881317890172014e-21" iyy="5.056378325344116e-08" iyz="8.470329472543003e-22" izz="6.689818006425498e-08"/>
  </inertial>
  <visual>
    <origin rpy="0 0 0" xyz="-0.089946 -0.075 -0.017389"/>
    <geometry>
      <mesh filename="meshes/Left_Front_Joint1.stl" scale="0.001 0.001 0.001"/>
    </geometry>
    <material name="black"/>
    <material/>
  </visual>
  <collision>
    <origin rpy="0 0 0" xyz="-0.089946 -0.075 -0.017389"/>
    <geometry>
      <mesh filename="meshes/Left_Front_Joint1.stl" scale="0.001 0.001 0.001"/>
    </geometry>
  </collision>
</link>

<link name="Lower_Left_Front_Servo1">
  <inertial>
    <origin rpy="0 0 0" xyz="0.007162501638801985 -0.016937460430151777 9.544679191508115e-05"/>
    <mass value="0.08509975852435851"/>
    <inertia ixx="4.855621768027913e-06" ixy="3.42882023236801e-07" ixz="-2.74306685419984e-09" iyy="1.6667854646009502e-05" iyz="4.571776864647028e-09" izz="1.606662695776014e-05"/>
  </inertial>
  <visual>
    <origin rpy="0 0 0" xyz="-0.089946 -0.07 -0.017389"/>
    <geometry>
      <mesh filename="meshes/Lower_Left_Front_Servo1.stl" scale="0.001 0.001 0.001"/>
    </geometry>
    <material name="black"/>
    <material/>
  </visual>
  <collision>
    <origin rpy="0 0 0" xyz="-0.089946 -0.07 -0.017389"/>
    <geometry>
      <mesh filename="meshes/Lower_Left_Front_Servo1.stl" scale="0.001 0.001 0.001"/>
    </geometry>
  </collision>
</link>

<link name="Lower_Left_Front_Leg1">
  <inertial>
    <origin rpy="0 0 0" xyz="0.023694680517413982 0.0 -0.0010203254505736503"/>
    <mass value="0.012527915218877713"/>
    <inertia ixx="8.926369168539721e-07" ixy="1.3552527156068805e-20" ixz="2.8908702763973346e-07" iyy="7.941025292395562e-06" iyz="-3.3881317890172014e-21" izz="7.257186962522926e-06"/>
  </inertial>
  <visual>
    <origin rpy="0 0 0" xyz="-0.089946 -0.065 -0.017389"/>
    <geometry>
      <mesh filename="meshes/Lower_Left_Front_Leg1.stl" scale="0.001 0.001 0.001"/>
    </geometry>
    <material name="wood"/>
    <material/>
  </visual>
  <collision>
    <origin rpy="0 0 0" xyz="-0.089946 -0.065 -0.017389"/>
    <geometry>
      <mesh filename="meshes/Lower_Left_Front_Leg1.stl" scale="0.001 0.001 0.001"/>
    </geometry>
  </collision>
</link>

<link name="Left_Front_Paw1">
  <inertial>
    <origin rpy="0 0 0" xyz="-3.311588045173952e-07 -1.3877787807814457e-17 -5.1111090505762125e-08"/>
    <mass value="0.009860673647584237"/>
    <inertia ixx="7.395505070385627e-07" ixy="0.0" ixz="-3.3881317890172014e-21" iyy="1.1093257522928218e-06" iyz="1.6940658945086007e-21" izz="7.395505070386982e-07"/>
  </inertial>
  <visual>
    <origin rpy="0 0 0" xyz="-0.15996 -0.065 -0.016117"/>
    <geometry>
      <mesh filename="meshes/Left_Front_Paw1.stl" scale="0.001 0.001 0.001"/>
    </geometry>
    <material name="white"/>
    <material/>
  </visual>
  <collision>
    <origin rpy="0 0 0" xyz="-0.15996 -0.065 -0.016117"/>
    <geometry>
      <mesh filename="meshes/Left_Front_Paw1.stl" scale="0.001 0.001 0.001"/>
    </geometry>
  </collision>
</link>

<joint name="R_Rear_Body_Hip_Servo" type="fixed">
  <origin rpy="0 0 0" xyz="-0.074132 -0.05 0.094571"/>
  <parent link="base_link"/>
  <child link="Upper_Right_Rear_Servo1"/>
</joint>

<joint name="R_Rear_Hip_Servo_Thigh" type="continuous">
  <origin rpy="0 0 0" xyz="-0.0158 -0.025 -0.0118"/>
  <parent link="Upper_Right_Rear_Servo1"/>
  <child link="Upper_Right_Rear_Leg1"/>
  <axis xyz="0.0 -1.0 0.0"/>
</joint>
<transmission name="R_Rear_Hip_Servo_Thigh_tran">
  <type>transmission_interface/SimpleTransmission</type>
  <joint name="R_Rear_Hip_Servo_Thigh">
    <hardwareInterface>PositionJointInterface</hardwareInterface>
  </joint>
  <actuator name="R_Rear_Hip_Servo_Thigh_actr">
    <hardwareInterface>PositionJointInterface</hardwareInterface>
    <mechanicalReduction>1</mechanicalReduction>
  </actuator>
</transmission>

<joint name="R_Rear_Thigh_Knee" type="fixed">
  <origin rpy="0 0 0" xyz="-3e-06 0.0 -0.065333"/>
  <parent link="Upper_Right_Rear_Leg1"/>
  <child link="Right_Rear_Joint1"/>
</joint>

<joint name="R_Rear_Knee_Servo" type="continuous">
  <origin rpy="0 0 0" xyz="0.0 0.005 0.0"/>
  <parent link="Right_Rear_Joint1"/>
  <child link="Lower_Right_Rear_Servo1"/>
  <axis xyz="0.0 -1.0 0.0"/>
</joint>
<transmission name="R_Rear_Knee_Servo_tran">
  <type>transmission_interface/SimpleTransmission</type>
  <joint name="R_Rear_Knee_Servo">
    <hardwareInterface>PositionJointInterface</hardwareInterface>
  </joint>
  <actuator name="R_Rear_Knee_Servo_actr">
    <hardwareInterface>PositionJointInterface</hardwareInterface>
    <mechanicalReduction>1</mechanicalReduction>
  </actuator>
</transmission>

<joint name="R_Rear_Knee_Calf" type="fixed">
  <origin rpy="0 0 0" xyz="0.0 0.005 0.0"/>
  <parent link="Lower_Right_Rear_Servo1"/>
  <child link="Lower_Right_Rear_Leg1"/>
</joint>

<joint name="R_Rear_Calf_Paw" type="fixed">
  <origin rpy="0 0 0" xyz="-0.070009 0.0 -0.001328"/>
  <parent link="Lower_Right_Rear_Leg1"/>
  <child link="Right_Rear_Paw1"/>
</joint>

<joint name="R_Front_Body_Hip_Servo" type="fixed">
  <origin rpy="0 0 0" xyz="0.072881 -0.05 0.095719"/>
  <parent link="base_link"/>
  <child link="Upper_Right_Front_Servo1"/>
</joint>

<joint name="R_Front_Hip_Servo_Thigh" type="continuous">
  <origin rpy="0 0 0" xyz="0.017117 -0.025 -0.013038"/>
  <parent link="Upper_Right_Front_Servo1"/>
  <child link="Upper_Right_Front_Leg1"/>
  <axis xyz="0.0 -1.0 0.0"/>
</joint>
<transmission name="R_Front_Hip_Servo_Thigh_tran">
  <type>transmission_interface/SimpleTransmission</type>
  <joint name="R_Front_Hip_Servo_Thigh">
    <hardwareInterface>PositionJointInterface</hardwareInterface>
  </joint>
  <actuator name="R_Front_Hip_Servo_Thigh_actr">
    <hardwareInterface>PositionJointInterface</hardwareInterface>
    <mechanicalReduction>1</mechanicalReduction>
  </actuator>
</transmission>

<joint name="R_Front_Thigh_Knee" type="fixed">
  <origin rpy="0 0 0" xyz="-6.1e-05 0.0 -0.065471"/>
  <parent link="Upper_Right_Front_Leg1"/>
  <child link="Right_Front_Joint1"/>
</joint>

<joint name="R_Front_Knee_Servo" type="continuous">
  <origin rpy="0 0 0" xyz="0.0 0.005 0.0"/>
  <parent link="Right_Front_Joint1"/>
  <child link="Lower_Right_Front_Servo1"/>
  <axis xyz="0.0 1.0 0.0"/>
</joint>
<transmission name="R_Front_Knee_Servo_tran">
  <type>transmission_interface/SimpleTransmission</type>
  <joint name="R_Front_Knee_Servo">
    <hardwareInterface>PositionJointInterface</hardwareInterface>
  </joint>
  <actuator name="R_Front_Knee_Servo_actr">
    <hardwareInterface>PositionJointInterface</hardwareInterface>
    <mechanicalReduction>1</mechanicalReduction>
  </actuator>
</transmission>

<joint name="R_Front_Knee_Calf" type="fixed">
  <origin rpy="0 0 0" xyz="0.0 0.005 0.0"/>
  <parent link="Lower_Right_Front_Servo1"/>
  <child link="Lower_Right_Front_Leg1"/>
</joint>

<joint name="R_Front_Calf_Paw" type="fixed">
  <origin rpy="0 0 0" xyz="0.069979 0.0 -0.001189"/>
  <parent link="Lower_Right_Front_Leg1"/>
  <child link="Right_Front_Paw1"/>
</joint>

<joint name="Body_Neck" type="fixed">
  <origin rpy="0 0 0" xyz="0.079697 0.0 0.112197"/>
  <parent link="base_link"/>
  <child link="Neck_Servo1"/>
</joint>

<joint name="Body_Neck_Servo" type="continuous">
  <origin rpy="0 0 0" xyz="0.01823 4e-06 0.013589"/>
  <parent link="Neck_Servo1"/>
  <child link="Neck1"/>
  <axis xyz="0.707107 0.0 0.707107"/>
</joint>
<transmission name="Body_Neck_Servo_tran">
  <type>transmission_interface/SimpleTransmission</type>
  <joint name="Body_Neck_Servo">
    <hardwareInterface>PositionJointInterface</hardwareInterface>
  </joint>
  <actuator name="Body_Neck_Servo_actr">
    <hardwareInterface>PositionJointInterface</hardwareInterface>
    <mechanicalReduction>1</mechanicalReduction>
  </actuator>
</transmission>

<joint name="Neck_Head_Servo" type="continuous">
  <origin rpy="0 0 0" xyz="0.027356 -0.030018 -0.003863"/>
  <parent link="Neck1"/>
  <child link="Head_Servo1"/>
  <axis xyz="0.0 1.0 -0.0"/>
</joint>
<transmission name="Neck_Head_Servo_tran">
  <type>transmission_interface/SimpleTransmission</type>
  <joint name="Neck_Head_Servo">
    <hardwareInterface>PositionJointInterface</hardwareInterface>
  </joint>
  <actuator name="Neck_Head_Servo_actr">
    <hardwareInterface>PositionJointInterface</hardwareInterface>
    <mechanicalReduction>1</mechanicalReduction>
  </actuator>
</transmission>

<joint name="Head_Servo_Head" type="fixed">
  <origin rpy="0 0 0" xyz="-0.000216 0.012967 0.006236"/>
  <parent link="Head_Servo1"/>
  <child link="Head1"/>
</joint>

<joint name="Body_PyBoard" type="fixed">
  <origin rpy="0 0 0" xyz="-7.2e-05 0.0475 0.102498"/>
  <parent link="base_link"/>
  <child link="Electronics1"/>
</joint>

<joint name="Body_Battery" type="fixed">
  <origin rpy="0 0 0" xyz="0.0 0.0 0.0725"/>
  <parent link="base_link"/>
  <child link="Battery1"/>
</joint>

<joint name="Body_Tail_Servo" type="fixed">
  <origin rpy="0 0 0" xyz="-0.079697 0.0 0.112197"/>
  <parent link="base_link"/>
  <child link="Tail_Servo1"/>
</joint>

<joint name="Tail_Servo_Tail" type="continuous">
  <origin rpy="0 0 0" xyz="-0.014421 -1.2e-05 0.017043"/>
  <parent link="Tail_Servo1"/>
  <child link="Tail1"/>
  <axis xyz="-0.707107 0.0 0.707107"/>
</joint>
<transmission name="Tail_Servo_Tail_tran">
  <type>transmission_interface/SimpleTransmission</type>
  <joint name="Tail_Servo_Tail">
    <hardwareInterface>PositionJointInterface</hardwareInterface>
  </joint>
  <actuator name="Tail_Servo_Tail_actr">
    <hardwareInterface>PositionJointInterface</hardwareInterface>
    <mechanicalReduction>1</mechanicalReduction>
  </actuator>
</transmission>

<joint name="L_Rear_Body_Hip_Servo" type="fixed">
  <origin rpy="0 0 0" xyz="-0.074132 0.05 0.094571"/>
  <parent link="base_link"/>
  <child link="Upper_Left_Rear_Servo1"/>
</joint>

<joint name="L_Rear_Hip_Servo_Thigh" type="continuous">
  <origin rpy="0 0 0" xyz="-0.0159 0.025 -0.0119"/>
  <parent link="Upper_Left_Rear_Servo1"/>
  <child link="Upper_Left_Rear_Leg1"/>
  <axis xyz="0.0 1.0 0.0"/>
</joint>
<transmission name="L_Rear_Hip_Servo_Thigh_tran">
  <type>transmission_interface/SimpleTransmission</type>
  <joint name="L_Rear_Hip_Servo_Thigh">
    <hardwareInterface>PositionJointInterface</hardwareInterface>
  </joint>
  <actuator name="L_Rear_Hip_Servo_Thigh_actr">
    <hardwareInterface>PositionJointInterface</hardwareInterface>
    <mechanicalReduction>1</mechanicalReduction>
  </actuator>
</transmission>

<joint name="L_Rear_Thigh_Knee" type="fixed">
  <origin rpy="0 0 0" xyz="5.7e-05 0.0 -0.065394"/>
  <parent link="Upper_Left_Rear_Leg1"/>
  <child link="Left_Rear_Joint1"/>
</joint>

<joint name="L_Rear_Knee_Servo" type="continuous">
  <origin rpy="0 0 0" xyz="0.0 -0.005 0.0"/>
  <parent link="Left_Rear_Joint1"/>
  <child link="Lower_Left_Rear_Servo1"/>
  <axis xyz="0.0 1.0 0.0"/>
</joint>
<transmission name="L_Rear_Knee_Servo_tran">
  <type>transmission_interface/SimpleTransmission</type>
  <joint name="L_Rear_Knee_Servo">
    <hardwareInterface>PositionJointInterface</hardwareInterface>
  </joint>
  <actuator name="L_Rear_Knee_Servo_actr">
    <hardwareInterface>PositionJointInterface</hardwareInterface>
    <mechanicalReduction>1</mechanicalReduction>
  </actuator>
</transmission>

<joint name="L_Rear_Knee_Calf" type="fixed">
  <origin rpy="0 0 0" xyz="0.0 -0.005 0.0"/>
  <parent link="Lower_Left_Rear_Servo1"/>
  <child link="Lower_Left_Rear_Leg1"/>
</joint>

<joint name="L_Rear_Calf_Paw" type="fixed">
  <origin rpy="0 0 0" xyz="-0.069999 0.0 -0.001247"/>
  <parent link="Lower_Left_Rear_Leg1"/>
  <child link="Left_Rear_Paw1"/>
</joint>

<joint name="L_Front_Body_Hip_Servo" type="fixed">
  <origin rpy="0 0 0" xyz="0.072933 0.05 0.095716"/>
  <parent link="base_link"/>
  <child link="Upper_Left_Front_Servo1"/>
</joint>

<joint name="L_Front_Hip_Servo_Thigh" type="continuous">
  <origin rpy="0 0 0" xyz="0.017042 0.025 -0.012996"/>
  <parent link="Upper_Left_Front_Servo1"/>
  <child link="Upper_Left_Front_Leg1"/>
  <axis xyz="0.0 1.0 0.0"/>
</joint>
<transmission name="L_Front_Hip_Servo_Thigh_tran">
  <type>transmission_interface/SimpleTransmission</type>
  <joint name="L_Front_Hip_Servo_Thigh">
    <hardwareInterface>PositionJointInterface</hardwareInterface>
  </joint>
  <actuator name="L_Front_Hip_Servo_Thigh_actr">
    <hardwareInterface>PositionJointInterface</hardwareInterface>
    <mechanicalReduction>1</mechanicalReduction>
  </actuator>
</transmission>

<joint name="L_Front_Thigh_Knee" type="fixed">
  <origin rpy="0 0 0" xyz="-2.9e-05 0.0 -0.065331"/>
  <parent link="Upper_Left_Front_Leg1"/>
  <child link="Left_Front_Joint1"/>
</joint>

<joint name="L_Front_Knee_Servo" type="continuous">
  <origin rpy="0 0 0" xyz="0.0 -0.005 0.0"/>
  <parent link="Left_Front_Joint1"/>
  <child link="Lower_Left_Front_Servo1"/>
  <axis xyz="0.0 1.0 0.0"/>
</joint>
<transmission name="L_Front_Knee_Servo_tran">
  <type>transmission_interface/SimpleTransmission</type>
  <joint name="L_Front_Knee_Servo">
    <hardwareInterface>PositionJointInterface</hardwareInterface>
  </joint>
  <actuator name="L_Front_Knee_Servo_actr">
    <hardwareInterface>PositionJointInterface</hardwareInterface>
    <mechanicalReduction>1</mechanicalReduction>
  </actuator>
</transmission>

<joint name="L_Front_Knee_Calf" type="fixed">
  <origin rpy="0 0 0" xyz="0.0 -0.005 0.0"/>
  <parent link="Lower_Left_Front_Servo1"/>
  <child link="Lower_Left_Front_Leg1"/>
</joint>

<joint name="L_Front_Calf_Paw" type="fixed">
  <origin rpy="0 0 0" xyz="0.070014 0.0 -0.001272"/>
  <parent link="Lower_Left_Front_Leg1"/>
  <child link="Left_Front_Paw1"/>
</joint>

</robot>
