<?xml version="1.0"?>
<robot name="Nybble">

    <material name="blue">
        <color rgba="0 0 0.8 1"/>
    </material>
    <material name="black">
        <color rgba="0 0 0 1"/>
    </material>

    <link name="torso">       
        <visual>
            <geometry>
                <box size="0.12 0.10 0.005"/>
            </geometry>
            <material name="blue"/>
        </visual>
      
        <collision>
              <geometry>
                    <box size="0.12 0.10 0.005"/>
              </geometry>
              <origin xyz="0 0 0"/>
        </collision>

        <inertial>
              <origin xyz="0 0 0"/>
              <mass value="0.2"/>
              <inertia ixx="0.0002" iyy="0.0003"  izz="0.0004" ixy="0.0" ixz="0.0" iyz="0.0"/>
        </inertial>
    </link>


    <link name="left_upper_arm">
        <visual>
            <origin xyz="0.00 .00 -0.025" rpy="0 0 0" />
            <geometry>
              <cylinder radius="0.001" length="0.05"/>
            </geometry>
            <material name="black"/>
        </visual>

        <collision>
            <geometry>
              <cylinder radius="0.001" length="0.05"/>
            </geometry>
            <origin xyz="0.00 .00 -0.025" rpy="0 0 0" />
        </collision>

        <inertial>
            <origin xyz=".0 .00 0.0" rpy="0 0 0" />
            <mass value="0.025"/>
            <inertia ixx="0.0" ixy="0.0" ixz="0.0" iyy="0.0" iyz="0.0" izz="0.0"/>
        </inertial>
    </link>   

    <link name="right_upper_arm">
            <visual>
                <origin xyz="0.00 .00 -0.025" rpy="0 0 0" />
                <geometry>
                  <cylinder radius="0.001" length="0.05"/>
                </geometry>
                <material name="black"/>
            </visual>

            <collision>
                <geometry>
                  <cylinder radius="0.001" length="0.05"/>
                </geometry>
                <origin xyz="0.00 .00 -0.025" rpy="0 0 0" />
            </collision>

            <inertial>
                <origin xyz=".0 .00 0.0" rpy="0 0 0" />
                <mass value="0.025"/>
                <inertia ixx="0.0" ixy="0.0" ixz="0.0" iyy="0.0" iyz="0.0" izz="0.0"/>
            </inertial>
        </link>   



    <link name="left_lower_arm">
        <visual>
            <origin xyz="0.00 .00 -0.025" rpy="0 0 0" />
            <geometry>
              <cylinder radius="0.001" length="0.05"/>
            </geometry>
            <material name="black"/>
        </visual>

        <collision>
            <geometry>
              <cylinder radius="0.001" length="0.05"/>
            </geometry>
            <origin xyz="0.00 .00 -0.025" rpy="0 0 0" />
        </collision>


        <inertial>
            <origin xyz=".0 .00 0.0" rpy="0 0 0" />
            <mass value="0.075"/>
            <inertia ixx="0.0" ixy="0.0" ixz="0.0" iyy="0.0" iyz="0.0" izz="0.0"/>
        </inertial>
    </link>   




    

    <link name="right_lower_arm">
        <visual>
            <origin xyz="0.00 .00 -0.025" rpy="0 0 0" />
            <geometry>
              <cylinder radius="0.001" length="0.05"/>
            </geometry>
            <material name="black"/>
        </visual>

        <collision>
            <geometry>
              <cylinder radius="0.001" length="0.05"/>
            </geometry>
            <origin xyz="0.00 .00 -0.025" rpy="0 0 0" />
        </collision>

        <inertial>
            <origin xyz=".0 .00 0.0" rpy="0 0 0" />
            <mass value="0.075"/>
            <inertia ixx="0.0" ixy="0.0" ixz="0.0" iyy="0.0" iyz="0.0" izz="0.0"/>
        </inertial>
    </link>   

    <link name="right_upper_leg">
        <visual>
            <origin xyz="0.00 .00 -0.025" rpy="0 0 0" />
            <geometry>
              <cylinder radius="0.001" length="0.05"/>
            </geometry>
            <material name="black"/>
        </visual>

        <collision>
            <geometry>
              <cylinder radius="0.001" length="0.05"/>
            </geometry>
            <origin xyz="0.00 .00 -0.025" rpy="0 0 0" />
        </collision>

        <inertial>
            <origin xyz=".0 .00 0.0" rpy="0 0 0" />
            <mass value="0.025"/>
            <inertia ixx="0.0" ixy="0.0" ixz="0.0" iyy="0.0" iyz="0.0" izz="0.0"/>
        </inertial>
    </link>   

    <link name="right_lower_leg">
        <visual>
            <origin xyz="0.00 .00 -0.025" rpy="0 0 0" />
            <geometry>
              <cylinder radius="0.001" length="0.05"/>
            </geometry>
            <material name="black"/>
        </visual>

        <collision>
            <geometry>
              <cylinder radius="0.001" length="0.05"/>
            </geometry>
            <origin xyz="0.00 .00 -0.025" rpy="0 0 0" />
        </collision>

        <inertial>
            <origin xyz=".0 .00 0.0" rpy="0 0 0" />
            <mass value="0.075"/>
            <inertia ixx="0.0" ixy="0.0" ixz="0.0" iyy="0.0" iyz="0.0" izz="0.0"/>
        </inertial>
    </link>   


    <link name="left_upper_leg">
        <visual>
            <origin xyz="0.00 .00 -0.025" rpy="0 0 0" />
            <geometry>
              <cylinder radius="0.001" length="0.05"/>
            </geometry>
            <material name="black"/>
        </visual>

        <collision>
            <geometry>
              <cylinder radius="0.001" length="0.05"/>
            </geometry>
            <origin xyz="0.00 .00 -0.025" rpy="0 0 0" />
        </collision>

        <inertial>
            <origin xyz=".0 .00 0.0" rpy="0 0 0" />
            <mass value="0.025"/>
            <inertia ixx="0.0" ixy="0.0" ixz="0.0" iyy="0.0" iyz="0.0" izz="0.0"/>
        </inertial>
    </link>   

    <link name="left_lower_leg">
        <visual>
            <origin xyz="0.00 .00 -0.025" rpy="0 0 0" />
            <geometry>
              <cylinder radius="0.001" length="0.05"/>
            </geometry>
            <material name="black"/>
        </visual>

        <collision>
            <geometry>
              <cylinder radius="0.001" length="0.05"/>
            </geometry>
            <origin xyz="0.00 .00 -0.025" rpy="0 0 0" />
        </collision>

        <inertial>
            <origin xyz=".0 .00 0.0" rpy="0 0 0" />
            <mass value="0.075"/>
            <inertia ixx="0.0" ixy="0.0" ixz="0.0" iyy="0.0" iyz="0.0" izz="0.0"/>
        </inertial>
    </link>   




    <joint name="shoulder_left" type="revolute">
          <axis xyz="0 1 0"/>
          <origin xyz="0.06 0.05 0" rpy="0 0 0"/>
          <parent link="torso"/>
          <child link="left_upper_arm"/>
          <limit effort="0" lower="-1.57" upper="1.57" velocity="0"/>
    </joint>

    <joint name="shoulder_right" type="revolute">
          <axis xyz="0 1 0"/>
          <origin xyz="0.06 -0.05 0" rpy="0 0 0"/>
          <parent link="torso"/>
          <child link="right_upper_arm"/>
          <limit effort="0" lower="-1.57" upper="1.57" velocity="0"/>
    </joint>

    <joint name="hip_right" type="revolute">
          <axis xyz="0 1 0"/>
          <origin xyz="-0.06 -0.05 0" rpy="0 0 0"/>
          <parent link="torso"/>
          <child link="right_upper_leg"/>
          <limit effort="0" lower="-1.57" upper="1.57" velocity="0"/>
    </joint>

    <joint name="hip_left" type="revolute">
          <axis xyz="0 1 0"/>
          <origin xyz="-0.06 0.05 0" rpy="0 0 0"/>
          <parent link="torso"/>
          <child link="left_upper_leg"/>
          <limit effort="0" lower="-1.57" upper="1.57" velocity="0"/>
    </joint>

    <joint name="elbow_left" type="revolute">
          <axis xyz="0 1 0"/>
          <origin xyz="0.00 0.00 -0.05" rpy="0 -1.57 0"/>
          <parent link="left_upper_arm"/>
          <child link="left_lower_arm"/>
          <limit effort="0" lower="-1.57" upper="1.57" velocity="0"/>
    </joint>

    <joint name="elbow_right" type="revolute">
          <axis xyz="0 1 0"/>
          <origin xyz="0.00 0.00 -0.05" rpy="0 -1.57 0"/>
          <parent link="right_upper_arm"/>
          <child link="right_lower_arm"/>
          <limit effort="0" lower="-1.57" upper="1.57" velocity="0"/>
    </joint>


    <joint name="knee_right" type="revolute">
          <axis xyz="0 1 0"/>
          <origin xyz="0.00 0.00 -0.05" rpy="0 1.57 0"/>
          <parent link="right_upper_leg"/>
          <child link="right_lower_leg"/>
          <limit effort="0" lower="-1.57" upper="1.57" velocity="0"/>
    </joint>   

    <joint name="knee_left" type="revolute">
          <axis xyz="0 1 0"/>
          <origin xyz="0.00 0.00 -0.05" rpy="0 1.57 0"/>
          <parent link="left_upper_leg"/>
          <child link="left_lower_leg"/>
          <limit effort="0" lower="-1.57" upper="1.57" velocity="0"/>
    </joint>    

</robot>

